<?xml version='1.0'?>
<robot xmlns:xacro="http://www.ros.org/wiki/xacro">

    <xacro:macro name="wheel" params="side x y z sign">

        <link name='wheel_${side}_link'>
            <visual name='wheel_${side}_visual'>
                <origin xyz="${(sign*0.1)/8} 0 0" rpy="0 ${pi/2} 0"/>
                <geometry>
                    <cylinder length="${(0.1)/4}" radius="${0.15/2}"/>
                </geometry>
                <material name="orange"/>
            </visual>

            <xacro:inertial_cylinder mass="2.5" length="${(0.1)/4}" radius="${0.15/2}">
                <origin xyz="${(sign*0.1)/8} 0 0" rpy="0 ${pi/2} 0"/>
            </xacro:inertial_cylinder>

            <collision>
               <origin xyz="${(sign*0.1)/8} 0 0" rpy="0 ${pi/2} 0"/>
                <geometry>
                    <cylinder length="${(0.1)/4}" radius="${0.15/2}"/>
                </geometry>
            </collision>

        </link>
         
        <joint name="wheel_${side}_joint" type="continuous">
            <origin xyz="${x*sign} ${y} ${z}" rpy="0 0 0"/>
            <axis xyz="1 0 0" />
            <limit effort="100" velocity="50"/>
            <joint_properties damping="0.5" friction="0.1"/>

            <child link="wheel_${side}_link"/>
            <parent link="base_link"/>
        </joint>

        <transmission name="wheel_${side}_trans">
            <type>transmission_interface/SimpleTransmission</type>
            <joint name="wheel_${side}_joint">
                <hardwareInterface>hardware_interface/EffortJointInterface</hardwareInterface>
            </joint>
            <actuator name="wheel_${side}_motor">
                <hardwareInterface>hardware_interface/EffortJointInterface</hardwareInterface>
                <mechanicalReduction>1</mechanicalReduction>
            </actuator>
        </transmission>

    </xacro:macro>
</robot>